<?xml version="1.0" ?>
<robot name="WHEELBASE" xmlns:xacro="http://www.ros.org/wiki/xacro">

<xacro:include filename="$(find WHEELBASE_description)/urdf/materials.xacro" />
<xacro:include filename="$(find WHEELBASE_description)/urdf/WHEELBASE.trans" />
<xacro:include filename="$(find WHEELBASE_description)/urdf/WHEELBASE.gazebo" />
<link name="base_link">
  <inertial>
    <origin xyz="0.31284579770446164 0.21309636765692727 0.09311470488492443" rpy="0 0 0"/>
    <mass value="70.33156451953299"/>
    <inertia ixx="1.980497" iyy="1.335951" izz="3.287143" ixy="-0.0" iyz="-0.0" ixz="0.0"/>
  </inertial>
  <visual>
    <origin xyz="0 0 0" rpy="0 0 0"/>
    <geometry>
      <mesh filename="package://WHEELBASE_description/meshes/base_link.stl" scale="0.001 0.001 0.001"/>
    </geometry>
    <material name="silver"/>
  </visual>
  <collision>
    <origin xyz="0 0 0" rpy="0 0 0"/>
    <geometry>
      <mesh filename="package://WHEELBASE_description/meshes/base_link.stl" scale="0.001 0.001 0.001"/>
    </geometry>
  </collision>
</link>

<link name="Component10_1">
  <inertial>
    <origin xyz="-0.46873 -0.084002 -0.118115" rpy="0 0 0"/>
    <mass value="0.0"/>
    <inertia ixx="0.0" iyy="0.0" izz="0.0" ixy="0.0" iyz="0.0" ixz="0.0"/>
  </inertial>
  <visual>
    <origin xyz="-0.46873 -0.084002 -0.118115" rpy="0 0 0"/>
    <geometry>
      <mesh filename="package://WHEELBASE_description/meshes/Component10_1.stl" scale="0.001 0.001 0.001"/>
    </geometry>
    <material name="silver"/>
  </visual>
  <collision>
    <origin xyz="-0.46873 -0.084002 -0.118115" rpy="0 0 0"/>
    <geometry>
      <mesh filename="package://WHEELBASE_description/meshes/Component10_1.stl" scale="0.001 0.001 0.001"/>
    </geometry>
  </collision>
</link>

<link name="Component8_1">
  <inertial>
    <origin xyz="-0.156961 -0.084002 -0.118115" rpy="0 0 0"/>
    <mass value="0.0"/>
    <inertia ixx="0.0" iyy="0.0" izz="0.0" ixy="0.0" iyz="0.0" ixz="0.0"/>
  </inertial>
  <visual>
    <origin xyz="-0.156961 -0.084002 -0.118115" rpy="0 0 0"/>
    <geometry>
      <mesh filename="package://WHEELBASE_description/meshes/Component8_1.stl" scale="0.001 0.001 0.001"/>
    </geometry>
    <material name="silver"/>
  </visual>
  <collision>
    <origin xyz="-0.156961 -0.084002 -0.118115" rpy="0 0 0"/>
    <geometry>
      <mesh filename="package://WHEELBASE_description/meshes/Component8_1.stl" scale="0.001 0.001 0.001"/>
    </geometry>
  </collision>
</link>

<link name="Component9_1">
  <inertial>
    <origin xyz="-0.312846 -0.424002 -0.118115" rpy="0 0 0"/>
    <mass value="0.0"/>
    <inertia ixx="0.0" iyy="0.0" izz="0.0" ixy="0.0" iyz="0.0" ixz="0.0"/>
  </inertial>
  <visual>
    <origin xyz="-0.312846 -0.424002 -0.118115" rpy="0 0 0"/>
    <geometry>
      <mesh filename="package://WHEELBASE_description/meshes/Component9_1.stl" scale="0.001 0.001 0.001"/>
    </geometry>
    <material name="silver"/>
  </visual>
  <collision>
    <origin xyz="-0.312846 -0.424002 -0.118115" rpy="0 0 0"/>
    <geometry>
      <mesh filename="package://WHEELBASE_description/meshes/Component9_1.stl" scale="0.001 0.001 0.001"/>
    </geometry>
  </collision>
</link>

<link name="Component7_1">
  <inertial>
    <origin xyz="-0.312821202295538 -0.12450188357914416 0.6568857048849248" rpy="0 0 0"/>
    <mass value="41.91899999999998"/>
    <inertia ixx="7.915851" iyy="7.915851" izz="0.112077" ixy="0.0" iyz="-0.0" ixz="-0.0"/>
  </inertial>
  <visual>
    <origin xyz="-0.625667 -0.298004 -0.161229" rpy="0 0 0"/>
    <geometry>
      <mesh filename="package://WHEELBASE_description/meshes/Component7_1.stl" scale="0.001 0.001 0.001"/>
    </geometry>
    <material name="silver"/>
  </visual>
  <collision>
    <origin xyz="-0.625667 -0.298004 -0.161229" rpy="0 0 0"/>
    <geometry>
      <mesh filename="package://WHEELBASE_description/meshes/Component7_1.stl" scale="0.001 0.001 0.001"/>
    </geometry>
  </collision>
</link>

<link name="Component19_1">
  <inertial>
    <origin xyz="-1.2317951106510794e-05 1.1642085651075718e-07 -0.03876676158490564" rpy="0 0 0"/>
    <mass value="8.125143264664759"/>
    <inertia ixx="0.012769" iyy="0.013881" izz="0.016655" ixy="-0.0" iyz="-0.0" ixz="3e-06"/>
  </inertial>
  <visual>
    <origin xyz="-0.312846 -0.424002 -0.068115" rpy="0 0 0"/>
    <geometry>
      <mesh filename="package://WHEELBASE_description/meshes/Component19_1.stl" scale="0.001 0.001 0.001"/>
    </geometry>
    <material name="silver"/>
  </visual>
  <collision>
    <origin xyz="-0.312846 -0.424002 -0.068115" rpy="0 0 0"/>
    <geometry>
      <mesh filename="package://WHEELBASE_description/meshes/Component19_1.stl" scale="0.001 0.001 0.001"/>
    </geometry>
  </collision>
</link>

<link name="Component18_1">
  <inertial>
    <origin xyz="-0.0030207849347674842 1.1642096639508104e-07 -2.9511509425095284e-07" rpy="0 0 0"/>
    <mass value="2.8010697707417975"/>
    <inertia ixx="0.008982" iyy="0.004757" izz="0.004757" ixy="-0.0" iyz="0.0" ixz="-0.0"/>
  </inertial>
  <visual>
    <origin xyz="-0.47373 -0.084002 -0.055615" rpy="0 0 0"/>
    <geometry>
      <mesh filename="package://WHEELBASE_description/meshes/Component18_1.stl" scale="0.001 0.001 0.001"/>
    </geometry>
    <material name="silver"/>
  </visual>
  <collision>
    <origin xyz="-0.47373 -0.084002 -0.055615" rpy="0 0 0"/>
    <geometry>
      <mesh filename="package://WHEELBASE_description/meshes/Component18_1.stl" scale="0.001 0.001 0.001"/>
    </geometry>
  </collision>
</link>

<link name="Component17_1">
  <inertial>
    <origin xyz="0.0030209530248860583 1.164208511261755e-07 -2.95115075273078e-07" rpy="0 0 0"/>
    <mass value="2.8010697707418943"/>
    <inertia ixx="0.008982" iyy="0.004757" izz="0.004757" ixy="-0.0" iyz="0.0" ixz="0.0"/>
  </inertial>
  <visual>
    <origin xyz="-0.147846 -0.085002 -0.055615" rpy="0 0 0"/>
    <geometry>
      <mesh filename="package://WHEELBASE_description/meshes/Component17_1.stl" scale="0.001 0.001 0.001"/>
    </geometry>
    <material name="silver"/>
  </visual>
  <collision>
    <origin xyz="-0.147846 -0.085002 -0.055615" rpy="0 0 0"/>
    <geometry>
      <mesh filename="package://WHEELBASE_description/meshes/Component17_1.stl" scale="0.001 0.001 0.001"/>
    </geometry>
  </collision>
</link>

<link name="Motor_v1_1">
  <inertial>
    <origin xyz="-0.35481269487349165 -0.17400188357914348 -0.08061429511507548" rpy="0 0 0"/>
    <mass value="0.391530547318601"/>
    <inertia ixx="3e-05" iyy="0.000703" izz="0.000703" ixy="-0.0" iyz="0.0" ixz="-0.0"/>
  </inertial>
  <visual>
    <origin xyz="-0.731552 -0.258004 -0.136229" rpy="0 0 0"/>
    <geometry>
      <mesh filename="package://WHEELBASE_description/meshes/Motor_v1_1.stl" scale="0.001 0.001 0.001"/>
    </geometry>
    <material name="silver"/>
  </visual>
  <collision>
    <origin xyz="-0.731552 -0.258004 -0.136229" rpy="0 0 0"/>
    <geometry>
      <mesh filename="package://WHEELBASE_description/meshes/Motor_v1_1.stl" scale="0.001 0.001 0.001"/>
    </geometry>
  </collision>
</link>

<link name="Motor_v1__1__1">
  <inertial>
    <origin xyz="-0.3308301370363861 -0.21300188357914393 -0.0806142951150754" rpy="0 0 0"/>
    <mass value="0.391530547318601"/>
    <inertia ixx="3e-05" iyy="0.000703" izz="0.000703" ixy="0.0" iyz="-0.0" ixz="0.0"/>
  </inertial>
  <visual>
    <origin xyz="-0.575667 -0.298004 -0.136229" rpy="0 0 0"/>
    <geometry>
      <mesh filename="package://WHEELBASE_description/meshes/Motor_v1__1__1.stl" scale="0.001 0.001 0.001"/>
    </geometry>
    <material name="silver"/>
  </visual>
  <collision>
    <origin xyz="-0.575667 -0.298004 -0.136229" rpy="0 0 0"/>
    <geometry>
      <mesh filename="package://WHEELBASE_description/meshes/Motor_v1__1__1.stl" scale="0.001 0.001 0.001"/>
    </geometry>
  </collision>
</link>

<joint name="Rigid 2" type="fixed">
  <origin xyz="0.46873 0.084002 0.118115" rpy="0 0 0"/>
  <parent link="base_link"/>
  <child link="Component10_1"/>
</joint>

<joint name="Rigid 3" type="fixed">
  <origin xyz="0.156961 0.084002 0.118115" rpy="0 0 0"/>
  <parent link="base_link"/>
  <child link="Component8_1"/>
</joint>

<joint name="Rigid 4" type="fixed">
  <origin xyz="0.312846 0.424002 0.118115" rpy="0 0 0"/>
  <parent link="base_link"/>
  <child link="Component9_1"/>
</joint>

<joint name="Rigid 5" type="fixed">
  <origin xyz="0.625667 0.298004 0.161229" rpy="0 0 0"/>
  <parent link="base_link"/>
  <child link="Component7_1"/>
</joint>

<joint name="Rigid 7" type="fixed">
  <origin xyz="0.312846 0.424002 0.068115" rpy="0 0 0"/>
  <parent link="base_link"/>
  <child link="Component19_1"/>
</joint>

<joint name="Revolute 8" type="continuous">
  <origin xyz="-0.257822 -0.174002 -0.080614" rpy="0 0 0"/>
  <parent link="Motor_v1_1"/>
  <child link="Component18_1"/>
  <axis xyz="1.0 -0.0 -0.0"/>
</joint>

<joint name="Revolute 9" type="continuous">
  <origin xyz="-0.427821 -0.213002 -0.080614" rpy="0 0 0"/>
  <parent link="Motor_v1__1__1"/>
  <child link="Component17_1"/>
  <axis xyz="-1.0 -0.0 0.0"/>
</joint>

<joint name="Rigid 10" type="fixed">
  <origin xyz="0.731552 0.258004 0.136229" rpy="0 0 0"/>
  <parent link="base_link"/>
  <child link="Motor_v1_1"/>
</joint>

<joint name="Rigid 11" type="fixed">
  <origin xyz="0.575667 0.298004 0.136229" rpy="0 0 0"/>
  <parent link="base_link"/>
  <child link="Motor_v1__1__1"/>
</joint>

</robot>
